<?xml version="1.0" encoding="utf-8"?>
<!-- This URDF was automatically created by SolidWorks to URDF Exporter! Originally created by Stephen Brawner (brawner@gmail.com) 
     Commit Version: 1.6.0-1-g15f4949  Build Version: 1.6.7594.29634
     For more information, please see http://wiki.ros.org/sw_urdf_exporter -->
<robot
  name="abb_irb140">

  <link name="world"/>
  <link name="base_link"/>

  <joint name="world_to_base_link" type="fixed">
    <origin
      xyz="0 0 0"
      rpy="0 0 0" />
    <parent link="world"/>
    <child link="base_link"/>
  </joint>

  <link
    name="base_mount_1">
    <inertial>
      <origin
        xyz="-2.77555756156289E-17 0 0.0249685346478045"
        rpy="0 0 0" />
      <mass
        value="12.4803650459151" />
      <inertia
        ixx="0.263009735409091"
        ixy="7.22801448323671E-18"
        ixz="1.3457113802009E-18"
        iyy="0.263009735409091"
        iyz="9.36980559644466E-19"
        izz="0.520827197410182" />
    </inertial>
    <visual>
      <origin rpy="0 0 0" xyz="0 0 0"/>
      <geometry>
        <mesh
          filename="package://abb_irb140_support/meshes/irb140/visual/base_link.stl" scale="0.01 0.01 0.01"/>
      </geometry>
      <material
        name="">
        <color
          rgba="0.792156862745098 0.819607843137255 0.933333333333333 1" />
      </material>
    </visual>
    <collision>
      <origin rpy="0 0 0" xyz="0 0 0"/>
        rpy="0 0 0" />
      <geometry>
        <mesh
          filename="package://abb_irb140_support/meshes/irb140/collision/base_link.stl" scale="0.01 0.01 0.01"/>
      </geometry>
    </collision>
  </link>
  <joint name="base_link_to_base_mount" type="fixed">
    <parent link="base_link"/>
    <child link="base_mount_1"/>
  </joint>
  <link
    name="link_1_1">
    <inertial>
      <origin
        xyz="2.77555756156289E-17 -1.11022302462516E-16 0.097976849171603"
        rpy="0 0 0" />
      <mass  
        value="1.80068602577615" />
      <inertia
        ixx="0.0119045831675013"
        ixy="-1.48038790812578E-19"
        ixz="1.0884512020216E-18"
        iyy="0.0102503494500899"
        iyz="-6.51420286586923E-19"
        izz="0.0048901686021603" />
    </inertial>
    <visual>
      <origin rpy="0 0 0" xyz="0 0 0"/>
      <geometry>
        <mesh
          filename="package://abb_irb140_support/meshes/irb140/visual/link_1.stl" scale="0.01 0.01 0.01"/>
      </geometry>
      <material
        name="">
        <color
          rgba="0.792156862745098 0.819607843137255 0.933333333333333 1" />
      </material>
    </visual>
    <collision>
      <origin rpy="0 0 0" xyz="0 0 0"/>
      <geometry>
        <mesh
          filename="package://abb_irb140_support/meshes/irb140/collision/link_1.stl" scale="0.01 0.01 0.01"/>
      </geometry>
    </collision>
  </link>
  <joint
    name="joint_1_1"
    type="revolute">
    <origin rpy="0 0 0" xyz="0 0 0"/>
    <parent
      link="base_mount_1" />
    <child
      link="link_1_1" />
    <axis
      xyz="0 0 1" />
    <limit
      lower="-3.15"
      upper="3.15"
      effort="9999999999999999"
      velocity="99999" />
  </joint>
  <link
    name="link_2_1">
    <inertial>
      <origin
        xyz="-8.32667268468867E-17 0 0.208641608364152"
        rpy="0 0 0" />
      <mass
        value="5.45229896526218" />
      <inertia
        ixx="0.143413588137143"
        ixy="9.75052379153749E-19"
        ixz="-1.03931943242608E-17"
        iyy="0.140495110157324"
        iyz="-2.35491472099339E-17"
        izz="0.0118420183045479" />
    </inertial>
    <visual>
      <origin rpy="0 0 0" xyz="-0.07 0 -0.352"/>
      <geometry>
        <mesh
          filename="package://abb_irb140_support/meshes/irb140/visual/link_2.stl" scale="0.01 0.01 0.01"/>
      </geometry>
      <material
        name="">
        <color
          rgba="0.792156862745098 0.819607843137255 0.933333333333333 1" />
      </material>
    </visual>
    <collision>
      <origin rpy="0 0 0" xyz="-0.07 0 -0.352"/>
      <geometry>
        <mesh
          filename="package://abb_irb140_support/meshes/irb140/collision/link_2.stl" scale="0.01 0.01 0.01"/>
      </geometry>
    </collision>
  </link>
  <joint
    name="joint_2_1"
    type="revolute">
    <origin rpy="0 0 0" xyz="0.070 0 0.352"/>
    <parent
      link="link_1_1" />
    <child
      link="link_2_1" />
    <axis
      xyz="0 1 0" />
    <limit
      lower="-3.15"
      upper="3.15"
      effort="9999999999999999"
      velocity="99999" />
  </joint>
  <link
    name="link_3_1">
    <inertial>
      <origin
        xyz="0.0274500571012589 -2.90326330198987E-08 2.88417890681458E-08"
        rpy="0 0 0" />
      <mass
        value="1.56522005865026" />
      <inertia
        ixx="0.00299683756846669"
        ixy="9.60755594981688E-09"
        ixz="2.30783868841078E-09"
        iyy="0.00386758425789166"
        iyz="-1.48019225653967E-08"
        izz="0.00515475196811992" />
    </inertial>
    <visual>
      <origin rpy="0 0 0" xyz="-0.07 0.065 -0.712"/>
      <geometry>
        <mesh
          filename="package://abb_irb140_support/meshes/irb140/visual/link_3.stl" scale="0.01 0.01 0.01"/>
      </geometry>
      <material
        name="">
        <color
          rgba="0.792156862745098 0.819607843137255 0.933333333333333 1" />
      </material>
    </visual>
    <collision>
      <origin rpy="0 0 0" xyz="-0.07 0.065 -0.712"/>
      <geometry>
        <mesh
          filename="package://abb_irb140_support/meshes/irb140/collision/link_3.stl" scale="0.01 0.01 0.01"/>
      </geometry>
    </collision>
  </link>
  <joint
    name="joint_3_1"
    type="revolute">
    <origin rpy="0 0 0" xyz="0 -0.065 0.360"/>
    <parent
      link="link_2_1" />
    <child
      link="link_3_1" />
    <axis
      xyz="0 1 0" />
    <limit
      lower="-3.15"
      upper="3.15"
      effort="9999999999999999"
      velocity="99999" />
  </joint>
  <link
    name="link_4_1">
    <inertial>
      <origin
        xyz="0.198811200967274 2.77555756156289E-16 1.11022302462516E-16"
        rpy="0 0 0" />
      <mass
        value="3.68052010677635" />
      <inertia
        ixx="0.0081369412404102"
        ixy="6.05852063809433E-20"
        ixz="-1.52899587296384E-18"
        iyy="0.0521876464335362"
        iyz="-2.70439880953382E-20"
        izz="0.0538418801509476" />
    </inertial>
    <visual>
      <origin rpy="0 0 0" xyz="-0.309 0 -0.712"/>
      <geometry>
        <mesh
          filename="package://abb_irb140_support/meshes/irb140/visual/link_4.stl" scale="0.01 0.01 0.01"/>
      </geometry>
      <material
        name="">
        <color
          rgba="0.792156862745098 0.819607843137255 0.933333333333333 1" />
      </material>
    </visual>
    <collision>
      <origin rpy="0 0 0" xyz="-0.309 0 -0.712"/>
      <geometry>
        <mesh
          filename="package://abb_irb140_support/meshes/irb140/collision/link_4.stl" scale="0.01 0.01 0.01"/>
      </geometry>
    </collision>
  </link>
  <joint
    name="joint_4_1"
    type="revolute">
    <origin rpy="0 0 0" xyz="0.239 0.065 0"/>
    <parent
      link="link_3_1" />
    <child
      link="link_4_1" />
    <axis
      xyz="1 0 0" />
    <limit
      lower="-3.15"
      upper="3.15"
      effort="9999999999999999"
      velocity="99999" />
  </joint>
  <link
    name="link_5_1">
    <inertial>
      <origin
        xyz="0.0245451654248717 -3.31323111724124E-08 1.75528557244675E-08"
        rpy="0 0 0" />
      <mass
        value="1.51495432847619" />
      <inertia
        ixx="0.00295662575449907"
        ixy="8.53466409627663E-09"
        ixz="2.12796454223232E-09"
        iyy="0.00344899075210009"
        iyz="-1.52965000603224E-08"
        izz="0.00473615740417172" />
    </inertial>
    <visual>
      <origin rpy="0 0 0" xyz="-0.450 0 -0.712"/>
      <geometry>
        <mesh
          filename="package://abb_irb140_support/meshes/irb140/visual/link_5.stl" scale="0.01 0.01 0.01"/>
      </geometry>
      <material
        name="">
        <color
          rgba="0.792156862745098 0.819607843137255 0.933333333333333 1" />
      </material>
    </visual>
    <collision>
      <origin rpy="0 0 0" xyz="-0.450 0 -0.712"/>
      <geometry>
        <mesh
          filename="package://abb_irb140_support/meshes/irb140/collision/link_5.stl" scale="0.01 0.01 0.01"/>
      </geometry>
    </collision>
  </link>
  <joint
    name="joint_5_1"
    type="revolute">
    <origin rpy="0 0 0" xyz="0.141 0 0"/>
    <parent
      link="link_4_1" />
    <child
      link="link_5_1" />
    <axis
      xyz="0 1 0" />
    <limit
      lower="-3.15"
      upper="3.15"
      effort="9999999999999999"
      velocity="99999" />
  </joint>
  <link
    name="link_6_1">
    <inertial>
      <origin
        xyz="0.0230448073562005 -2.22044604925031E-16 -6.66133814775094E-16"
        rpy="0 0 0" />
      <mass
        value="0.546084058391925" />
      <inertia
        ixx="0.00217868736433955"
        ixy="-3.68881012579868E-19"
        ixz="8.40312633921998E-20"
        iyy="0.000544073429846913"
        iyz="4.65242280180247E-19"
        izz="0.00203494728197032" />
    </inertial>
    <visual>
      <origin rpy="0 0 0" xyz="-0.515 0 -0.712"/>
      <geometry>
        <mesh
          filename="package://abb_irb140_support/meshes/irb140/visual/link_6.stl" scale="0.01 0.01 0.01"/>
      </geometry>
      <material
        name="">
        <color
          rgba="0.792156862745098 0.819607843137255 0.933333333333333 1" />
      </material>
    </visual>
    <collision>
      <origin rpy="0 0 0" xyz="-0.515 0 -0.712"/>
      <geometry>
        <mesh
          filename="package://abb_irb140_support/meshes/irb140/collision/link_6.stl" scale="0.01 0.01 0.01"/>
      </geometry>
    </collision>
  </link>
  <joint
    name="joint_6_1"
    type="revolute">
    <origin rpy="0 0 0" xyz="0.065 0 0"/>
    <parent
      link="link_5_1" />
    <child
      link="link_6_1" />
    <axis
      xyz="1 0 0" />
    <limit
      lower="-3.15"
      upper="3.15"
      effort="9999999999999999"
      velocity="99999" />
  </joint>

<!-- #########################  Slave bot  ###########################-->

  <link
    name="base_mount_2">
    <inertial>
      <origin
        xyz="-2.77555756156289E-17 0 0.0249685346478045"
        rpy="0 0 0" />
      <mass
        value="12.4803650459151" />
      <inertia
        ixx="0.263009735409091"
        ixy="7.22801448323671E-18"
        ixz="1.3457113802009E-18"
        iyy="0.263009735409091"
        iyz="9.36980559644466E-19"
        izz="0.520827197410182" />
    </inertial>
    <visual>
      <origin rpy="0 0 0" xyz="0 0 0"/>
      <geometry>
        <mesh
          filename="package://abb_irb140_support/meshes/irb140/visual/base_link.stl" scale="0.01 0.01 0.01"/>
      </geometry>
      <material
        name="">
        <color
          rgba="0.792156862745098 0.819607843137255 0.933333333333333 1" />
      </material>
    </visual>
    <collision>
      <origin rpy="0 0 0" xyz="0 0 0"/>
        rpy="0 0 0" />
      <geometry>
        <mesh
          filename="package://abb_irb140_support/meshes/irb140/collision/base_link.stl" scale="0.01 0.01 0.01"/>
      </geometry>
    </collision>
  </link>
  <joint name="base_link_to_base_mount_2" type="fixed">
    <origin rpy="0 0 0" xyz="0 0.5 0"/>
    <parent link="base_link"/>
    <child link="base_mount_2"/>
  </joint>
  <link
    name="link_1_2">
    <inertial>
      <origin
        xyz="2.77555756156289E-17 -1.11022302462516E-16 0.097976849171603"
        rpy="0 0 0" />
      <mass  
        value="1.80068602577615" />
      <inertia
        ixx="0.0119045831675013"
        ixy="-1.48038790812578E-19"
        ixz="1.0884512020216E-18"
        iyy="0.0102503494500899"
        iyz="-6.51420286586923E-19"
        izz="0.0048901686021603" />
    </inertial>
    <visual>
      <origin rpy="0 0 0" xyz="0 0 0"/>
      <geometry>
        <mesh
          filename="package://abb_irb140_support/meshes/irb140/visual/link_1.stl" scale="0.01 0.01 0.01"/>
      </geometry>
      <material
        name="">
        <color
          rgba="0.792156862745098 0.819607843137255 0.933333333333333 1" />
      </material>
    </visual>
    <collision>
      <origin rpy="0 0 0" xyz="0 0 0"/>
      <geometry>
        <mesh
          filename="package://abb_irb140_support/meshes/irb140/collision/link_1.stl" scale="0.01 0.01 0.01"/>
      </geometry>
    </collision>
  </link>
  <joint
    name="joint_1_2"
    type="revolute">
    <origin rpy="0 0 0" xyz="0 0 0"/>
    <parent
      link="base_mount_2" />
    <child
      link="link_1_2" />
    <axis
      xyz="0 0 1" />
    <limit
      lower="-3.15"
      upper="3.15"
      effort="9999999999999999"
      velocity="99999" />
  </joint>
  <link
    name="link_2_2">
    <inertial>
      <origin
        xyz="-8.32667268468867E-17 0 0.208641608364152"
        rpy="0 0 0" />
      <mass
        value="5.45229896526218" />
      <inertia
        ixx="0.143413588137143"
        ixy="9.75052379153749E-19"
        ixz="-1.03931943242608E-17"
        iyy="0.140495110157324"
        iyz="-2.35491472099339E-17"
        izz="0.0118420183045479" />
    </inertial>
    <visual>
      <origin rpy="0 0 0" xyz="-0.07 0 -0.352"/>
      <geometry>
        <mesh
          filename="package://abb_irb140_support/meshes/irb140/visual/link_2.stl" scale="0.01 0.01 0.01"/>
      </geometry>
      <material
        name="">
        <color
          rgba="0.792156862745098 0.819607843137255 0.933333333333333 1" />
      </material>
    </visual>
    <collision>
      <origin rpy="0 0 0" xyz="-0.07 0 -0.352"/>
      <geometry>
        <mesh
          filename="package://abb_irb140_support/meshes/irb140/collision/link_2.stl" scale="0.01 0.01 0.01"/>
      </geometry>
    </collision>
  </link>
  <joint
    name="joint_2_2"
    type="revolute">
    <origin rpy="0 0 0" xyz="0.070 0 0.352"/>
    <parent
      link="link_1_2" />
    <child
      link="link_2_2" />
    <axis
      xyz="0 1 0" />
    <limit
      lower="-3.15"
      upper="3.15"
      effort="9999999999999999"
      velocity="99999" />
  </joint>
  <link
    name="link_3_2">
    <inertial>
      <origin
        xyz="0.0274500571012589 -2.90326330198987E-08 2.88417890681458E-08"
        rpy="0 0 0" />
      <mass
        value="1.56522005865026" />
      <inertia
        ixx="0.00299683756846669"
        ixy="9.60755594981688E-09"
        ixz="2.30783868841078E-09"
        iyy="0.00386758425789166"
        iyz="-1.48019225653967E-08"
        izz="0.00515475196811992" />
    </inertial>
    <visual>
      <origin rpy="0 0 0" xyz="-0.07 0.065 -0.712"/>
      <geometry>
        <mesh
          filename="package://abb_irb140_support/meshes/irb140/visual/link_3.stl" scale="0.01 0.01 0.01"/>
      </geometry>
      <material
        name="">
        <color
          rgba="0.792156862745098 0.819607843137255 0.933333333333333 1" />
      </material>
    </visual>
    <collision>
      <origin rpy="0 0 0" xyz="-0.07 0.065 -0.712"/>
      <geometry>
        <mesh
          filename="package://abb_irb140_support/meshes/irb140/collision/link_3.stl" scale="0.01 0.01 0.01"/>
      </geometry>
    </collision>
  </link>
  <joint
    name="joint_3_2"
    type="revolute">
    <origin rpy="0 0 0" xyz="0 -0.065 0.360"/>
    <parent
      link="link_2_2" />
    <child
      link="link_3_2" />
    <axis
      xyz="0 1 0" />
    <limit
      lower="-3.15"
      upper="3.15"
      effort="9999999999999999"
      velocity="99999" />
  </joint>
  <link
    name="link_4_2">
    <inertial>
      <origin
        xyz="0.198811200967274 2.77555756156289E-16 1.11022302462516E-16"
        rpy="0 0 0" />
      <mass
        value="3.68052010677635" />
      <inertia
        ixx="0.0081369412404102"
        ixy="6.05852063809433E-20"
        ixz="-1.52899587296384E-18"
        iyy="0.0521876464335362"
        iyz="-2.70439880953382E-20"
        izz="0.0538418801509476" />
    </inertial>
    <visual>
      <origin rpy="0 0 0" xyz="-0.309 0 -0.712"/>
      <geometry>
        <mesh
          filename="package://abb_irb140_support/meshes/irb140/visual/link_4.stl" scale="0.01 0.01 0.01"/>
      </geometry>
      <material
        name="">
        <color
          rgba="0.792156862745098 0.819607843137255 0.933333333333333 1" />
      </material>
    </visual>
    <collision>
      <origin rpy="0 0 0" xyz="-0.309 0 -0.712"/>
      <geometry>
        <mesh
          filename="package://abb_irb140_support/meshes/irb140/collision/link_4.stl" scale="0.01 0.01 0.01"/>
      </geometry>
    </collision>
  </link>
  <joint
    name="joint_4_2"
    type="revolute">
    <origin rpy="0 0 0" xyz="0.239 0.065 0"/>
    <parent
      link="link_3_2" />
    <child
      link="link_4_2" />
    <axis
      xyz="1 0 0" />
    <limit
      lower="-3.15"
      upper="3.15"
      effort="9999999999999999"
      velocity="99999" />
  </joint>
  <link
    name="link_5_2">
    <inertial>
      <origin
        xyz="0.0245451654248717 -3.31323111724124E-08 1.75528557244675E-08"
        rpy="0 0 0" />
      <mass
        value="1.51495432847619" />
      <inertia
        ixx="0.00295662575449907"
        ixy="8.53466409627663E-09"
        ixz="2.12796454223232E-09"
        iyy="0.00344899075210009"
        iyz="-1.52965000603224E-08"
        izz="0.00473615740417172" />
    </inertial>
    <visual>
      <origin rpy="0 0 0" xyz="-0.450 0 -0.712"/>
      <geometry>
        <mesh
          filename="package://abb_irb140_support/meshes/irb140/visual/link_5.stl" scale="0.01 0.01 0.01"/>
      </geometry>
      <material
        name="">
        <color
          rgba="0.792156862745098 0.819607843137255 0.933333333333333 1" />
      </material>
    </visual>
    <collision>
      <origin rpy="0 0 0" xyz="-0.450 0 -0.712"/>
      <geometry>
        <mesh
          filename="package://abb_irb140_support/meshes/irb140/collision/link_5.stl" scale="0.01 0.01 0.01"/>
      </geometry>
    </collision>
  </link>
  <joint
    name="joint_5_2"
    type="revolute">
    <origin rpy="0 0 0" xyz="0.141 0 0"/>
    <parent
      link="link_4_2" />
    <child
      link="link_5_2" />
    <axis
      xyz="0 1 0" />
    <limit
      lower="-3.15"
      upper="3.15"
      effort="9999999999999999"
      velocity="99999" />
  </joint>
  <link
    name="link_6_2">
    <inertial>
      <origin
        xyz="0.0230448073562005 -2.22044604925031E-16 -6.66133814775094E-16"
        rpy="0 0 0" />
      <mass
        value="0.546084058391925" />
      <inertia
        ixx="0.00217868736433955"
        ixy="-3.68881012579868E-19"
        ixz="8.40312633921998E-20"
        iyy="0.000544073429846913"
        iyz="4.65242280180247E-19"
        izz="0.00203494728197032" />
    </inertial>
    <visual>
      <origin rpy="0 0 0" xyz="-0.515 0 -0.712"/>
      <geometry>
        <mesh
          filename="package://abb_irb140_support/meshes/irb140/visual/link_6.stl" scale="0.01 0.01 0.01"/>
      </geometry>
      <material
        name="">
        <color
          rgba="0.792156862745098 0.819607843137255 0.933333333333333 1" />
      </material>
    </visual>
    <collision>
      <origin rpy="0 0 0" xyz="-0.515 0 -0.712"/>
      <geometry>
        <mesh
          filename="package://abb_irb140_support/meshes/irb140/collision/link_6.stl" scale="0.01 0.01 0.01"/>
      </geometry>
    </collision>
  </link>
  <joint
    name="joint_6_2"
    type="revolute">
    <origin rpy="0 0 0" xyz="0.065 0 0"/>
    <parent
      link="link_5_2" />
    <child
      link="link_6_2" />
    <axis
      xyz="1 0 0" />
    <limit
      lower="-3.15"
      upper="3.15"
      effort="9999999999999999"
      velocity="99999" />
  </joint>

<!-- #########################  Transmission element  ###########################-->


<transmission name="tran1_1">
      <type>transmission_interface/SimpleTransmission</type>
      <joint name="joint_1_1">
        <hardwareInterface>hardware_interface/VelocityJointInterface</hardwareInterface>
      </joint>
      <actuator name="motor1_1">
        <hardwareInterface>hardware_interface/VelocityJointInterface</hardwareInterface>
        <mechanicalReduction>1</mechanicalReduction>
      </actuator>
    </transmission>

<transmission name="tran2_1">
      <type>transmission_interface/SimpleTransmission</type>
      <joint name="joint_2_1">
        <hardwareInterface>hardware_interface/VelocityJointInterface</hardwareInterface>
      </joint>
      <actuator name="motor2_1">
        <hardwareInterface>hardware_interface/VelocityJointInterface</hardwareInterface>
        <mechanicalReduction>1</mechanicalReduction>
      </actuator>
    </transmission>

<transmission name="tran3_1">
      <type>transmission_interface/SimpleTransmission</type>
      <joint name="joint_3_1">
        <hardwareInterface>hardware_interface/VelocityJointInterface</hardwareInterface>
      </joint>
      <actuator name="motor3_1">
        <hardwareInterface>hardware_interface/VelocityJointInterface</hardwareInterface>
        <mechanicalReduction>1</mechanicalReduction>
      </actuator>
    </transmission>

<transmission name="tran4_1">
      <type>transmission_interface/SimpleTransmission</type>
      <joint name="joint_4_1">
        <hardwareInterface>hardware_interface/VelocityJointInterface</hardwareInterface>
      </joint>
      <actuator name="motor4_1">
        <hardwareInterface>hardware_interface/VelocityJointInterface</hardwareInterface>
        <mechanicalReduction>1</mechanicalReduction>
      </actuator>
    </transmission>

<transmission name="tran5_1">
      <type>transmission_interface/SimpleTransmission</type>
      <joint name="joint_5_1">
        <hardwareInterface>hardware_interface/VelocityJointInterface</hardwareInterface>
      </joint>
      <actuator name="motor5_1">
        <hardwareInterface>hardware_interface/VelocityJointInterface</hardwareInterface>
        <mechanicalReduction>1</mechanicalReduction>
      </actuator>
    </transmission>

<transmission name="tran6_1">
      <type>transmission_interface/SimpleTransmission</type>
      <joint name="joint_6_1">
        <hardwareInterface>hardware_interface/VelocityJointInterface</hardwareInterface>
      </joint>
      <actuator name="motor6_1">
        <hardwareInterface>hardware_interface/VelocityJointInterface</hardwareInterface>
        <mechanicalReduction>1</mechanicalReduction>
      </actuator>
    </transmission>

<transmission name="tran1_2">
      <type>transmission_interface/SimpleTransmission</type>
      <joint name="joint_1_2">
        <hardwareInterface>hardware_interface/VelocityJointInterface</hardwareInterface>
      </joint>
      <actuator name="motor1_2">
        <hardwareInterface>hardware_interface/VelocityJointInterface</hardwareInterface>
        <mechanicalReduction>1</mechanicalReduction>
      </actuator>
    </transmission>

<transmission name="tran2_2">
      <type>transmission_interface/SimpleTransmission</type>
      <joint name="joint_2_2">
        <hardwareInterface>hardware_interface/VelocityJointInterface</hardwareInterface>
      </joint>
      <actuator name="motor2_2">
        <hardwareInterface>hardware_interface/VelocityJointInterface</hardwareInterface>
        <mechanicalReduction>1</mechanicalReduction>
      </actuator>
    </transmission>

<transmission name="tran3_2">
      <type>transmission_interface/SimpleTransmission</type>
      <joint name="joint_3_2">
        <hardwareInterface>hardware_interface/VelocityJointInterface</hardwareInterface>
      </joint>
      <actuator name="motor3_2">
        <hardwareInterface>hardware_interface/VelocityJointInterface</hardwareInterface>
        <mechanicalReduction>1</mechanicalReduction>
      </actuator>
    </transmission>

<transmission name="tran4_2">
      <type>transmission_interface/SimpleTransmission</type>
      <joint name="joint_4_2">
        <hardwareInterface>hardware_interface/VelocityJointInterface</hardwareInterface>
      </joint>
      <actuator name="motor4_2">
        <hardwareInterface>hardware_interface/VelocityJointInterface</hardwareInterface>
        <mechanicalReduction>1</mechanicalReduction>
      </actuator>
    </transmission>

<transmission name="tran5_2">
      <type>transmission_interface/SimpleTransmission</type>
      <joint name="joint_5_2">
        <hardwareInterface>hardware_interface/VelocityJointInterface</hardwareInterface>
      </joint>
      <actuator name="motor5_2">
        <hardwareInterface>hardware_interface/VelocityJointInterface</hardwareInterface>
        <mechanicalReduction>1</mechanicalReduction>
      </actuator>
    </transmission>

<transmission name="tran6_2">
      <type>transmission_interface/SimpleTransmission</type>
      <joint name="joint_6_2">
        <hardwareInterface>hardware_interface/VelocityJointInterface</hardwareInterface>
      </joint>
      <actuator name="motor6_2">
        <hardwareInterface>hardware_interface/VelocityJointInterface</hardwareInterface>
        <mechanicalReduction>1</mechanicalReduction>
      </actuator>
    </transmission>

<!-- #########################  Gazebo element  ###########################-->

<gazebo>
  <plugin name="gazebo_ros_control" filename="libgazebo_ros_control.so">
    <robotNamespace>/abb_irb140</robotNamespace>
  </plugin>
</gazebo>

<gazebo reference="base_mount_1">
  <material>Gazebo/FlatBlack</material>
</gazebo>

<gazebo reference="link_1_1">
  <material>Gazebo/CoM</material>
</gazebo>

<gazebo reference="link_2_1">
  <material>Gazebo/Orange</material>
</gazebo>

<gazebo reference="link_3_1">
  <material>Gazebo/CoM</material>
</gazebo>

<gazebo reference="link_4_1">
  <material>Gazebo/Orange</material>
</gazebo>

<gazebo reference="link_5_1">
  <material>Gazebo/CoM</material>
</gazebo>

<gazebo reference="link_6_1">
  <material>Gazebo/CoM </material>
</gazebo>

<gazebo reference="base_mount_2">
  <material>Gazebo/FlatBlack</material>
</gazebo>

<gazebo reference="link_1_2">
  <material>Gazebo/CoM</material>
</gazebo>

<gazebo reference="link_2_2">
  <material>Gazebo/Orange</material>
</gazebo>

<gazebo reference="link_3_2">
  <material>Gazebo/CoM</material>
</gazebo>

<gazebo reference="link_4_2">
  <material>Gazebo/Orange</material>
</gazebo>

<gazebo reference="link_5_2">
  <material>Gazebo/CoM</material>
</gazebo>

<gazebo reference="link_6_2">
  <material>Gazebo/CoM </material>
</gazebo>


</robot>
